Traceback (most recent call last):
  File "/Users/agah/opt/anaconda3/envs/jbnew/lib/python3.6/site-packages/jupyter_cache/executors/utils.py", line 56, in single_nb_execution
    record_timing=False,
  File "/Users/agah/opt/anaconda3/envs/jbnew/lib/python3.6/site-packages/nbclient/client.py", line 1082, in execute
    return NotebookClient(nb=nb, resources=resources, km=km, **kwargs).execute()
  File "/Users/agah/opt/anaconda3/envs/jbnew/lib/python3.6/site-packages/nbclient/util.py", line 74, in wrapped
    return just_run(coro(*args, **kwargs))
  File "/Users/agah/opt/anaconda3/envs/jbnew/lib/python3.6/site-packages/nbclient/util.py", line 53, in just_run
    return loop.run_until_complete(coro)
  File "/Users/agah/opt/anaconda3/envs/jbnew/lib/python3.6/asyncio/base_events.py", line 488, in run_until_complete
    return future.result()
  File "/Users/agah/opt/anaconda3/envs/jbnew/lib/python3.6/site-packages/nbclient/client.py", line 536, in async_execute
    cell, index, execution_count=self.code_cells_executed + 1
  File "/Users/agah/opt/anaconda3/envs/jbnew/lib/python3.6/site-packages/nbclient/client.py", line 827, in async_execute_cell
    self._check_raise_for_error(cell, exec_reply)
  File "/Users/agah/opt/anaconda3/envs/jbnew/lib/python3.6/site-packages/nbclient/client.py", line 735, in _check_raise_for_error
    raise CellExecutionError.from_cell_and_msg(cell, exec_reply['content'])
nbclient.exceptions.CellExecutionError: An error occurred while executing the following cell:
------------------
# Read the first file to explore data
dset = read_ismrmrd(files[0], 'dataset')

# Parse header 
header = parse_ismrmd_header(dset.read_xml_header())

# See what's in the header
print('header has:',list(vars(header).keys()))
print('----')
print('header.encoding[0] has:',list(vars(header.encoding[0]).keys()))
------------------

[0;31m---------------------------------------------------------------------------[0m
[0;31mOSError[0m                                   Traceback (most recent call last)
[0;32m~/opt/anaconda3/envs/jbnew/lib/python3.6/site-packages/h5py/_hl/files.py[0m in [0;36mmake_fid[0;34m(name, mode, userblock_size, fapl, fcpl, swmr)[0m
[1;32m    201[0m         [0;32mtry[0m[0;34m:[0m[0;34m[0m[0;34m[0m[0m
[0;32m--> 202[0;31m             [0mfid[0m [0;34m=[0m [0mh5f[0m[0;34m.[0m[0mopen[0m[0;34m([0m[0mname[0m[0;34m,[0m [0mh5f[0m[0;34m.[0m[0mACC_RDWR[0m[0;34m,[0m [0mfapl[0m[0;34m=[0m[0mfapl[0m[0;34m)[0m[0;34m[0m[0;34m[0m[0m
[0m[1;32m    203[0m         [0;32mexcept[0m [0mIOError[0m[0;34m:[0m[0;34m[0m[0;34m[0m[0m

[0;32mh5py/_objects.pyx[0m in [0;36mh5py._objects.with_phil.wrapper[0;34m()[0m

[0;32mh5py/_objects.pyx[0m in [0;36mh5py._objects.with_phil.wrapper[0;34m()[0m

[0;32mh5py/h5f.pyx[0m in [0;36mh5py.h5f.open[0;34m()[0m

[0;31mOSError[0m: Unable to open file (unable to open file: name = './KSpace/sub-ismrm_ses-sunrise_acq-chord1.h5', errno = 2, error message = 'No such file or directory', flags = 1, o_flags = 2)

During handling of the above exception, another exception occurred:

[0;31mOSError[0m                                   Traceback (most recent call last)
[0;32m<ipython-input-3-19724ce40fda>[0m in [0;36m<module>[0;34m[0m
[1;32m      1[0m [0;31m# Read the first file to explore data[0m[0;34m[0m[0;34m[0m[0;34m[0m[0m
[0;32m----> 2[0;31m [0mdset[0m [0;34m=[0m [0mread_ismrmrd[0m[0;34m([0m[0mfiles[0m[0;34m[[0m[0;36m0[0m[0;34m][0m[0;34m,[0m [0;34m'dataset'[0m[0;34m)[0m[0;34m[0m[0;34m[0m[0m
[0m[1;32m      3[0m [0;34m[0m[0m
[1;32m      4[0m [0;31m# Parse header[0m[0;34m[0m[0;34m[0m[0;34m[0m[0m
[1;32m      5[0m [0mheader[0m [0;34m=[0m [0mparse_ismrmd_header[0m[0;34m([0m[0mdset[0m[0;34m.[0m[0mread_xml_header[0m[0;34m([0m[0;34m)[0m[0;34m)[0m[0;34m[0m[0;34m[0m[0m

[0;32m~/opt/anaconda3/envs/jbnew/lib/python3.6/site-packages/ismrmrd/hdf5.py[0m in [0;36m__init__[0;34m(self, filename, dataset_name, create_if_needed)[0m
[1;32m    148[0m         [0;31m# Open the file[0m[0;34m[0m[0;34m[0m[0;34m[0m[0m
[1;32m    149[0m         [0;32mif[0m [0mcreate_if_needed[0m[0;34m:[0m[0;34m[0m[0;34m[0m[0m
[0;32m--> 150[0;31m             [0mself[0m[0;34m.[0m[0m_file[0m [0;34m=[0m [0mh5py[0m[0;34m.[0m[0mFile[0m[0;34m([0m[0mfilename[0m[0;34m,[0m [0;34m'a'[0m[0;34m)[0m[0;34m[0m[0;34m[0m[0m
[0m[1;32m    151[0m         [0;32melse[0m[0;34m:[0m[0;34m[0m[0;34m[0m[0m
[1;32m    152[0m             [0mself[0m[0;34m.[0m[0m_file[0m [0;34m=[0m [0mh5py[0m[0;34m.[0m[0mFile[0m[0;34m([0m[0mfilename[0m[0;34m,[0m [0;34m'r+'[0m[0;34m)[0m[0;34m[0m[0;34m[0m[0m

[0;32m~/opt/anaconda3/envs/jbnew/lib/python3.6/site-packages/h5py/_hl/files.py[0m in [0;36m__init__[0;34m(self, name, mode, driver, libver, userblock_size, swmr, rdcc_nslots, rdcc_nbytes, rdcc_w0, track_order, fs_strategy, fs_persist, fs_threshold, **kwds)[0m
[1;32m    425[0m                                fapl, fcpl=make_fcpl(track_order=track_order, fs_strategy=fs_strategy,
[1;32m    426[0m                                fs_persist=fs_persist, fs_threshold=fs_threshold),
[0;32m--> 427[0;31m                                swmr=swmr)
[0m[1;32m    428[0m [0;34m[0m[0m
[1;32m    429[0m             [0;32mif[0m [0misinstance[0m[0;34m([0m[0mlibver[0m[0;34m,[0m [0mtuple[0m[0;34m)[0m[0;34m:[0m[0;34m[0m[0;34m[0m[0m

[0;32m~/opt/anaconda3/envs/jbnew/lib/python3.6/site-packages/h5py/_hl/files.py[0m in [0;36mmake_fid[0;34m(name, mode, userblock_size, fapl, fcpl, swmr)[0m
[1;32m    202[0m             [0mfid[0m [0;34m=[0m [0mh5f[0m[0;34m.[0m[0mopen[0m[0;34m([0m[0mname[0m[0;34m,[0m [0mh5f[0m[0;34m.[0m[0mACC_RDWR[0m[0;34m,[0m [0mfapl[0m[0;34m=[0m[0mfapl[0m[0;34m)[0m[0;34m[0m[0;34m[0m[0m
[1;32m    203[0m         [0;32mexcept[0m [0mIOError[0m[0;34m:[0m[0;34m[0m[0;34m[0m[0m
[0;32m--> 204[0;31m             [0mfid[0m [0;34m=[0m [0mh5f[0m[0;34m.[0m[0mcreate[0m[0;34m([0m[0mname[0m[0;34m,[0m [0mh5f[0m[0;34m.[0m[0mACC_EXCL[0m[0;34m,[0m [0mfapl[0m[0;34m=[0m[0mfapl[0m[0;34m,[0m [0mfcpl[0m[0;34m=[0m[0mfcpl[0m[0;34m)[0m[0;34m[0m[0;34m[0m[0m
[0m[1;32m    205[0m     [0;32melse[0m[0;34m:[0m[0;34m[0m[0;34m[0m[0m
[1;32m    206[0m         [0;32mraise[0m [0mValueError[0m[0;34m([0m[0;34m"Invalid mode; must be one of r, r+, w, w-, x, a"[0m[0;34m)[0m[0;34m[0m[0;34m[0m[0m

[0;32mh5py/_objects.pyx[0m in [0;36mh5py._objects.with_phil.wrapper[0;34m()[0m

[0;32mh5py/_objects.pyx[0m in [0;36mh5py._objects.with_phil.wrapper[0;34m()[0m

[0;32mh5py/h5f.pyx[0m in [0;36mh5py.h5f.create[0;34m()[0m

[0;31mOSError[0m: Unable to create file (unable to open file: name = './KSpace/sub-ismrm_ses-sunrise_acq-chord1.h5', errno = 2, error message = 'No such file or directory', flags = 15, o_flags = a02)
OSError: Unable to create file (unable to open file: name = './KSpace/sub-ismrm_ses-sunrise_acq-chord1.h5', errno = 2, error message = 'No such file or directory', flags = 15, o_flags = a02)

